Workbook

Sheet Prices
A1: =GOOGLEFINANCE("ASX:VAS","all",TODAY()-620,TODAY()) | H1: Change ASX:VAS to your fund (for example ASX:VGS). Google Sheets fills columns A to F.

Sheet Dip check
A1: Date | B1: Close | C1: High | D1: Low | E1: 50-day avg | F1: 200-day avg | G1: Bollinger lower band | H1: Gain | I1: Loss | J1: Avg gain (14) | K1: Avg loss (14) | L1: RSI (14) | M1: Stoch raw %K | N1: Stoch %K (3) | O1: RSI < 30 | P1: Stochastic < 20 | Q1: 50-day pullback | R1: 200-day pullback | S1: Below Bollinger | T1: Any signal today? | V1: Latest date | W1: =INDEX(A2:A401,COUNT(B2:B401))
A2: =IF(Prices!A2="","",Prices!A2) | B2: =IF(Prices!E2="","",Prices!E2) | C2: =IF(Prices!C2="","",Prices!C2) | D2: =IF(Prices!D2="","",Prices!D2) | O2: =IF(ISNUMBER(L2),L2<30,FALSE) | P2: =IF(ISNUMBER(N2),N2<20,FALSE) | Q2: =FALSE | R2: =FALSE | S2: =IF(ISNUMBER(G2),B2<G2,FALSE) | T2: =OR(O2,P2,Q2,R2,S2) | V2: Latest close | W2: =INDEX(B2:B401,COUNT(B2:B401))
A3: =IF(Prices!A3="","",Prices!A3) | B3: =IF(Prices!E3="","",Prices!E3) | C3: =IF(Prices!C3="","",Prices!C3) | D3: =IF(Prices!D3="","",Prices!D3) | H3: =MAX(B3-B2,0) | I3: =MAX(B2-B3,0) | O3: =IF(ISNUMBER(L3),L3<30,FALSE) | P3: =IF(ISNUMBER(N3),N3<20,FALSE) | Q3: =FALSE | R3: =FALSE | S3: =IF(ISNUMBER(G3),B3<G3,FALSE) | T3: =OR(O3,P3,Q3,R3,S3) | V3: RSI < 30 | W3: =INDEX(O2:O401,COUNT(B2:B401))
A4: =IF(Prices!A4="","",Prices!A4) | B4: =IF(Prices!E4="","",Prices!E4) | C4: =IF(Prices!C4="","",Prices!C4) | D4: =IF(Prices!D4="","",Prices!D4) | H4: =MAX(B4-B3,0) | I4: =MAX(B3-B4,0) | O4: =IF(ISNUMBER(L4),L4<30,FALSE) | P4: =IF(ISNUMBER(N4),N4<20,FALSE) | Q4: =FALSE | R4: =FALSE | S4: =IF(ISNUMBER(G4),B4<G4,FALSE) | T4: =OR(O4,P4,Q4,R4,S4) | V4: Stochastic < 20 | W4: =INDEX(P2:P401,COUNT(B2:B401))
A5: =IF(Prices!A5="","",Prices!A5) | B5: =IF(Prices!E5="","",Prices!E5) | C5: =IF(Prices!C5="","",Prices!C5) | D5: =IF(Prices!D5="","",Prices!D5) | H5: =MAX(B5-B4,0) | I5: =MAX(B4-B5,0) | O5: =IF(ISNUMBER(L5),L5<30,FALSE) | P5: =IF(ISNUMBER(N5),N5<20,FALSE) | Q5: =FALSE | R5: =FALSE | S5: =IF(ISNUMBER(G5),B5<G5,FALSE) | T5: =OR(O5,P5,Q5,R5,S5) | V5: 50-day pullback | W5: =INDEX(Q2:Q401,COUNT(B2:B401))
A6: =IF(Prices!A6="","",Prices!A6) | B6: =IF(Prices!E6="","",Prices!E6) | C6: =IF(Prices!C6="","",Prices!C6) | D6: =IF(Prices!D6="","",Prices!D6) | H6: =MAX(B6-B5,0) | I6: =MAX(B5-B6,0) | O6: =IF(ISNUMBER(L6),L6<30,FALSE) | P6: =IF(ISNUMBER(N6),N6<20,FALSE) | Q6: =FALSE | R6: =FALSE | S6: =IF(ISNUMBER(G6),B6<G6,FALSE) | T6: =OR(O6,P6,Q6,R6,S6) | V6: 200-day pullback | W6: =INDEX(R2:R401,COUNT(B2:B401))
A7: =IF(Prices!A7="","",Prices!A7) | B7: =IF(Prices!E7="","",Prices!E7) | C7: =IF(Prices!C7="","",Prices!C7) | D7: =IF(Prices!D7="","",Prices!D7) | H7: =MAX(B7-B6,0) | I7: =MAX(B6-B7,0) | O7: =IF(ISNUMBER(L7),L7<30,FALSE) | P7: =IF(ISNUMBER(N7),N7<20,FALSE) | Q7: =FALSE | R7: =FALSE | S7: =IF(ISNUMBER(G7),B7<G7,FALSE) | T7: =OR(O7,P7,Q7,R7,S7) | V7: Below Bollinger band | W7: =INDEX(S2:S401,COUNT(B2:B401))
A8: =IF(Prices!A8="","",Prices!A8) | B8: =IF(Prices!E8="","",Prices!E8) | C8: =IF(Prices!C8="","",Prices!C8) | D8: =IF(Prices!D8="","",Prices!D8) | H8: =MAX(B8-B7,0) | I8: =MAX(B7-B8,0) | O8: =IF(ISNUMBER(L8),L8<30,FALSE) | P8: =IF(ISNUMBER(N8),N8<20,FALSE) | Q8: =FALSE | R8: =FALSE | S8: =IF(ISNUMBER(G8),B8<G8,FALSE) | T8: =OR(O8,P8,Q8,R8,S8) | V8: Any signal today? | W8: =INDEX(T2:T401,COUNT(B2:B401))
A9: =IF(Prices!A9="","",Prices!A9) | B9: =IF(Prices!E9="","",Prices!E9) | C9: =IF(Prices!C9="","",Prices!C9) | D9: =IF(Prices!D9="","",Prices!D9) | H9: =MAX(B9-B8,0) | I9: =MAX(B8-B9,0) | O9: =IF(ISNUMBER(L9),L9<30,FALSE) | P9: =IF(ISNUMBER(N9),N9<20,FALSE) | Q9: =FALSE | R9: =FALSE | S9: =IF(ISNUMBER(G9),B9<G9,FALSE) | T9: =OR(O9,P9,Q9,R9,S9)
A10: =IF(Prices!A10="","",Prices!A10) | B10: =IF(Prices!E10="","",Prices!E10) | C10: =IF(Prices!C10="","",Prices!C10) | D10: =IF(Prices!D10="","",Prices!D10) | H10: =MAX(B10-B9,0) | I10: =MAX(B9-B10,0) | O10: =IF(ISNUMBER(L10),L10<30,FALSE) | P10: =IF(ISNUMBER(N10),N10<20,FALSE) | Q10: =FALSE | R10: =FALSE | S10: =IF(ISNUMBER(G10),B10<G10,FALSE) | T10: =OR(O10,P10,Q10,R10,S10) | V10: A signal is read after the close and acted on the next trading day. Educational only, not advice.
A11: =IF(Prices!A11="","",Prices!A11) | B11: =IF(Prices!E11="","",Prices!E11) | C11: =IF(Prices!C11="","",Prices!C11) | D11: =IF(Prices!D11="","",Prices!D11) | H11: =MAX(B11-B10,0) | I11: =MAX(B10-B11,0) | O11: =IF(ISNUMBER(L11),L11<30,FALSE) | P11: =IF(ISNUMBER(N11),N11<20,FALSE) | Q11: =FALSE | R11: =FALSE | S11: =IF(ISNUMBER(G11),B11<G11,FALSE) | T11: =OR(O11,P11,Q11,R11,S11)
A12: =IF(Prices!A12="","",Prices!A12) | B12: =IF(Prices!E12="","",Prices!E12) | C12: =IF(Prices!C12="","",Prices!C12) | D12: =IF(Prices!D12="","",Prices!D12) | H12: =MAX(B12-B11,0) | I12: =MAX(B11-B12,0) | O12: =IF(ISNUMBER(L12),L12<30,FALSE) | P12: =IF(ISNUMBER(N12),N12<20,FALSE) | Q12: =FALSE | R12: =FALSE | S12: =IF(ISNUMBER(G12),B12<G12,FALSE) | T12: =OR(O12,P12,Q12,R12,S12)
A13: =IF(Prices!A13="","",Prices!A13) | B13: =IF(Prices!E13="","",Prices!E13) | C13: =IF(Prices!C13="","",Prices!C13) | D13: =IF(Prices!D13="","",Prices!D13) | H13: =MAX(B13-B12,0) | I13: =MAX(B12-B13,0) | O13: =IF(ISNUMBER(L13),L13<30,FALSE) | P13: =IF(ISNUMBER(N13),N13<20,FALSE) | Q13: =FALSE | R13: =FALSE | S13: =IF(ISNUMBER(G13),B13<G13,FALSE) | T13: =OR(O13,P13,Q13,R13,S13)
A14: =IF(Prices!A14="","",Prices!A14) | B14: =IF(Prices!E14="","",Prices!E14) | C14: =IF(Prices!C14="","",Prices!C14) | D14: =IF(Prices!D14="","",Prices!D14) | H14: =MAX(B14-B13,0) | I14: =MAX(B13-B14,0) | O14: =IF(ISNUMBER(L14),L14<30,FALSE) | P14: =IF(ISNUMBER(N14),N14<20,FALSE) | Q14: =FALSE | R14: =FALSE | S14: =IF(ISNUMBER(G14),B14<G14,FALSE) | T14: =OR(O14,P14,Q14,R14,S14)
A15: =IF(Prices!A15="","",Prices!A15) | B15: =IF(Prices!E15="","",Prices!E15) | C15: =IF(Prices!C15="","",Prices!C15) | D15: =IF(Prices!D15="","",Prices!D15) | H15: =MAX(B15-B14,0) | I15: =MAX(B14-B15,0) | M15: =IF(MAX(C2:C15)=MIN(D2:D15),50,100*(B15-MIN(D2:D15))/(MAX(C2:C15)-MIN(D2:D15))) | O15: =IF(ISNUMBER(L15),L15<30,FALSE) | P15: =IF(ISNUMBER(N15),N15<20,FALSE) | Q15: =FALSE | R15: =FALSE | S15: =IF(ISNUMBER(G15),B15<G15,FALSE) | T15: =OR(O15,P15,Q15,R15,S15)
A16: =IF(Prices!A16="","",Prices!A16) | B16: =IF(Prices!E16="","",Prices!E16) | C16: =IF(Prices!C16="","",Prices!C16) | D16: =IF(Prices!D16="","",Prices!D16) | H16: =MAX(B16-B15,0) | I16: =MAX(B15-B16,0) | J16: =AVERAGE(H3:H16) | K16: =AVERAGE(I3:I16) | L16: =IF(K16=0,100,100-100/(1+J16/K16)) | M16: =IF(MAX(C3:C16)=MIN(D3:D16),50,100*(B16-MIN(D3:D16))/(MAX(C3:C16)-MIN(D3:D16))) | O16: =IF(ISNUMBER(L16),L16<30,FALSE) | P16: =IF(ISNUMBER(N16),N16<20,FALSE) | Q16: =FALSE | R16: =FALSE | S16: =IF(ISNUMBER(G16),B16<G16,FALSE) | T16: =OR(O16,P16,Q16,R16,S16)
A17: =IF(Prices!A17="","",Prices!A17) | B17: =IF(Prices!E17="","",Prices!E17) | C17: =IF(Prices!C17="","",Prices!C17) | D17: =IF(Prices!D17="","",Prices!D17) | H17: =MAX(B17-B16,0) | I17: =MAX(B16-B17,0) | J17: =(J16*13+H17)/14 | K17: =(K16*13+I17)/14 | L17: =IF(K17=0,100,100-100/(1+J17/K17)) | M17: =IF(MAX(C4:C17)=MIN(D4:D17),50,100*(B17-MIN(D4:D17))/(MAX(C4:C17)-MIN(D4:D17))) | N17: =AVERAGE(M15:M17) | O17: =IF(ISNUMBER(L17),L17<30,FALSE) | P17: =IF(ISNUMBER(N17),N17<20,FALSE) | Q17: =FALSE | R17: =FALSE | S17: =IF(ISNUMBER(G17),B17<G17,FALSE) | T17: =OR(O17,P17,Q17,R17,S17)
A18: =IF(Prices!A18="","",Prices!A18) | B18: =IF(Prices!E18="","",Prices!E18) | C18: =IF(Prices!C18="","",Prices!C18) | D18: =IF(Prices!D18="","",Prices!D18) | H18: =MAX(B18-B17,0) | I18: =MAX(B17-B18,0) | J18: =(J17*13+H18)/14 | K18: =(K17*13+I18)/14 | L18: =IF(K18=0,100,100-100/(1+J18/K18)) | M18: =IF(MAX(C5:C18)=MIN(D5:D18),50,100*(B18-MIN(D5:D18))/(MAX(C5:C18)-MIN(D5:D18))) | N18: =AVERAGE(M16:M18) | O18: =IF(ISNUMBER(L18),L18<30,FALSE) | P18: =IF(ISNUMBER(N18),N18<20,FALSE) | Q18: =FALSE | R18: =FALSE | S18: =IF(ISNUMBER(G18),B18<G18,FALSE) | T18: =OR(O18,P18,Q18,R18,S18)
A19: =IF(Prices!A19="","",Prices!A19) | B19: =IF(Prices!E19="","",Prices!E19) | C19: =IF(Prices!C19="","",Prices!C19) | D19: =IF(Prices!D19="","",Prices!D19) | H19: =MAX(B19-B18,0) | I19: =MAX(B18-B19,0) | J19: =(J18*13+H19)/14 | K19: =(K18*13+I19)/14 | L19: =IF(K19=0,100,100-100/(1+J19/K19)) | M19: =IF(MAX(C6:C19)=MIN(D6:D19),50,100*(B19-MIN(D6:D19))/(MAX(C6:C19)-MIN(D6:D19))) | N19: =AVERAGE(M17:M19) | O19: =IF(ISNUMBER(L19),L19<30,FALSE) | P19: =IF(ISNUMBER(N19),N19<20,FALSE) | Q19: =FALSE | R19: =FALSE | S19: =IF(ISNUMBER(G19),B19<G19,FALSE) | T19: =OR(O19,P19,Q19,R19,S19)
A20: =IF(Prices!A20="","",Prices!A20) | B20: =IF(Prices!E20="","",Prices!E20) | C20: =IF(Prices!C20="","",Prices!C20) | D20: =IF(Prices!D20="","",Prices!D20) | H20: =MAX(B20-B19,0) | I20: =MAX(B19-B20,0) | J20: =(J19*13+H20)/14 | K20: =(K19*13+I20)/14 | L20: =IF(K20=0,100,100-100/(1+J20/K20)) | M20: =IF(MAX(C7:C20)=MIN(D7:D20),50,100*(B20-MIN(D7:D20))/(MAX(C7:C20)-MIN(D7:D20))) | N20: =AVERAGE(M18:M20) | O20: =IF(ISNUMBER(L20),L20<30,FALSE) | P20: =IF(ISNUMBER(N20),N20<20,FALSE) | Q20: =FALSE | R20: =FALSE | S20: =IF(ISNUMBER(G20),B20<G20,FALSE) | T20: =OR(O20,P20,Q20,R20,S20)
A21: =IF(Prices!A21="","",Prices!A21) | B21: =IF(Prices!E21="","",Prices!E21) | C21: =IF(Prices!C21="","",Prices!C21) | D21: =IF(Prices!D21="","",Prices!D21) | G21: =AVERAGE(B2:B21)-2*STDEV.P(B2:B21) | H21: =MAX(B21-B20,0) | I21: =MAX(B20-B21,0) | J21: =(J20*13+H21)/14 | K21: =(K20*13+I21)/14 | L21: =IF(K21=0,100,100-100/(1+J21/K21)) | M21: =IF(MAX(C8:C21)=MIN(D8:D21),50,100*(B21-MIN(D8:D21))/(MAX(C8:C21)-MIN(D8:D21))) | N21: =AVERAGE(M19:M21) | O21: =IF(ISNUMBER(L21),L21<30,FALSE) | P21: =IF(ISNUMBER(N21),N21<20,FALSE) | Q21: =FALSE | R21: =FALSE | S21: =IF(ISNUMBER(G21),B21<G21,FALSE) | T21: =OR(O21,P21,Q21,R21,S21)
A22: =IF(Prices!A22="","",Prices!A22) | B22: =IF(Prices!E22="","",Prices!E22) | C22: =IF(Prices!C22="","",Prices!C22) | D22: =IF(Prices!D22="","",Prices!D22) | G22: =AVERAGE(B3:B22)-2*STDEV.P(B3:B22) | H22: =MAX(B22-B21,0) | I22: =MAX(B21-B22,0) | J22: =(J21*13+H22)/14 | K22: =(K21*13+I22)/14 | L22: =IF(K22=0,100,100-100/(1+J22/K22)) | M22: =IF(MAX(C9:C22)=MIN(D9:D22),50,100*(B22-MIN(D9:D22))/(MAX(C9:C22)-MIN(D9:D22))) | N22: =AVERAGE(M20:M22) | O22: =IF(ISNUMBER(L22),L22<30,FALSE) | P22: =IF(ISNUMBER(N22),N22<20,FALSE) | Q22: =FALSE | R22: =FALSE | S22: =IF(ISNUMBER(G22),B22<G22,FALSE) | T22: =OR(O22,P22,Q22,R22,S22)
A23: =IF(Prices!A23="","",Prices!A23) | B23: =IF(Prices!E23="","",Prices!E23) | C23: =IF(Prices!C23="","",Prices!C23) | D23: =IF(Prices!D23="","",Prices!D23) | G23: =AVERAGE(B4:B23)-2*STDEV.P(B4:B23) | H23: =MAX(B23-B22,0) | I23: =MAX(B22-B23,0) | J23: =(J22*13+H23)/14 | K23: =(K22*13+I23)/14 | L23: =IF(K23=0,100,100-100/(1+J23/K23)) | M23: =IF(MAX(C10:C23)=MIN(D10:D23),50,100*(B23-MIN(D10:D23))/(MAX(C10:C23)-MIN(D10:D23))) | N23: =AVERAGE(M21:M23) | O23: =IF(ISNUMBER(L23),L23<30,FALSE) | P23: =IF(ISNUMBER(N23),N23<20,FALSE) | Q23: =FALSE | R23: =FALSE | S23: =IF(ISNUMBER(G23),B23<G23,FALSE) | T23: =OR(O23,P23,Q23,R23,S23)
A24: =IF(Prices!A24="","",Prices!A24) | B24: =IF(Prices!E24="","",Prices!E24) | C24: =IF(Prices!C24="","",Prices!C24) | D24: =IF(Prices!D24="","",Prices!D24) | G24: =AVERAGE(B5:B24)-2*STDEV.P(B5:B24) | H24: =MAX(B24-B23,0) | I24: =MAX(B23-B24,0) | J24: =(J23*13+H24)/14 | K24: =(K23*13+I24)/14 | L24: =IF(K24=0,100,100-100/(1+J24/K24)) | M24: =IF(MAX(C11:C24)=MIN(D11:D24),50,100*(B24-MIN(D11:D24))/(MAX(C11:C24)-MIN(D11:D24))) | N24: =AVERAGE(M22:M24) | O24: =IF(ISNUMBER(L24),L24<30,FALSE) | P24: =IF(ISNUMBER(N24),N24<20,FALSE) | Q24: =FALSE | R24: =FALSE | S24: =IF(ISNUMBER(G24),B24<G24,FALSE) | T24: =OR(O24,P24,Q24,R24,S24)
A25: =IF(Prices!A25="","",Prices!A25) | B25: =IF(Prices!E25="","",Prices!E25) | C25: =IF(Prices!C25="","",Prices!C25) | D25: =IF(Prices!D25="","",Prices!D25) | G25: =AVERAGE(B6:B25)-2*STDEV.P(B6:B25) | H25: =MAX(B25-B24,0) | I25: =MAX(B24-B25,0) | J25: =(J24*13+H25)/14 | K25: =(K24*13+I25)/14 | L25: =IF(K25=0,100,100-100/(1+J25/K25)) | M25: =IF(MAX(C12:C25)=MIN(D12:D25),50,100*(B25-MIN(D12:D25))/(MAX(C12:C25)-MIN(D12:D25))) | N25: =AVERAGE(M23:M25) | O25: =IF(ISNUMBER(L25),L25<30,FALSE) | P25: =IF(ISNUMBER(N25),N25<20,FALSE) | Q25: =FALSE | R25: =FALSE | S25: =IF(ISNUMBER(G25),B25<G25,FALSE) | T25: =OR(O25,P25,Q25,R25,S25)
A26: =IF(Prices!A26="","",Prices!A26) | B26: =IF(Prices!E26="","",Prices!E26) | C26: =IF(Prices!C26="","",Prices!C26) | D26: =IF(Prices!D26="","",Prices!D26) | G26: =AVERAGE(B7:B26)-2*STDEV.P(B7:B26) | H26: =MAX(B26-B25,0) | I26: =MAX(B25-B26,0) | J26: =(J25*13+H26)/14 | K26: =(K25*13+I26)/14 | L26: =IF(K26=0,100,100-100/(1+J26/K26)) | M26: =IF(MAX(C13:C26)=MIN(D13:D26),50,100*(B26-MIN(D13:D26))/(MAX(C13:C26)-MIN(D13:D26))) | N26: =AVERAGE(M24:M26) | O26: =IF(ISNUMBER(L26),L26<30,FALSE) | P26: =IF(ISNUMBER(N26),N26<20,FALSE) | Q26: =FALSE | R26: =FALSE | S26: =IF(ISNUMBER(G26),B26<G26,FALSE) | T26: =OR(O26,P26,Q26,R26,S26)
A27: =IF(Prices!A27="","",Prices!A27) | B27: =IF(Prices!E27="","",Prices!E27) | C27: =IF(Prices!C27="","",Prices!C27) | D27: =IF(Prices!D27="","",Prices!D27) | G27: =AVERAGE(B8:B27)-2*STDEV.P(B8:B27) | H27: =MAX(B27-B26,0) | I27: =MAX(B26-B27,0) | J27: =(J26*13+H27)/14 | K27: =(K26*13+I27)/14 | L27: =IF(K27=0,100,100-100/(1+J27/K27)) | M27: =IF(MAX(C14:C27)=MIN(D14:D27),50,100*(B27-MIN(D14:D27))/(MAX(C14:C27)-MIN(D14:D27))) | N27: =AVERAGE(M25:M27) | O27: =IF(ISNUMBER(L27),L27<30,FALSE) | P27: =IF(ISNUMBER(N27),N27<20,FALSE) | Q27: =FALSE | R27: =FALSE | S27: =IF(ISNUMBER(G27),B27<G27,FALSE) | T27: =OR(O27,P27,Q27,R27,S27)
A28: =IF(Prices!A28="","",Prices!A28) | B28: =IF(Prices!E28="","",Prices!E28) | C28: =IF(Prices!C28="","",Prices!C28) | D28: =IF(Prices!D28="","",Prices!D28) | G28: =AVERAGE(B9:B28)-2*STDEV.P(B9:B28) | H28: =MAX(B28-B27,0) | I28: =MAX(B27-B28,0) | J28: =(J27*13+H28)/14 | K28: =(K27*13+I28)/14 | L28: =IF(K28=0,100,100-100/(1+J28/K28)) | M28: =IF(MAX(C15:C28)=MIN(D15:D28),50,100*(B28-MIN(D15:D28))/(MAX(C15:C28)-MIN(D15:D28))) | N28: =AVERAGE(M26:M28) | O28: =IF(ISNUMBER(L28),L28<30,FALSE) | P28: =IF(ISNUMBER(N28),N28<20,FALSE) | Q28: =FALSE | R28: =FALSE | S28: =IF(ISNUMBER(G28),B28<G28,FALSE) | T28: =OR(O28,P28,Q28,R28,S28)
A29: =IF(Prices!A29="","",Prices!A29) | B29: =IF(Prices!E29="","",Prices!E29) | C29: =IF(Prices!C29="","",Prices!C29) | D29: =IF(Prices!D29="","",Prices!D29) | G29: =AVERAGE(B10:B29)-2*STDEV.P(B10:B29) | H29: =MAX(B29-B28,0) | I29: =MAX(B28-B29,0) | J29: =(J28*13+H29)/14 | K29: =(K28*13+I29)/14 | L29: =IF(K29=0,100,100-100/(1+J29/K29)) | M29: =IF(MAX(C16:C29)=MIN(D16:D29),50,100*(B29-MIN(D16:D29))/(MAX(C16:C29)-MIN(D16:D29))) | N29: =AVERAGE(M27:M29) | O29: =IF(ISNUMBER(L29),L29<30,FALSE) | P29: =IF(ISNUMBER(N29),N29<20,FALSE) | Q29: =FALSE | R29: =FALSE | S29: =IF(ISNUMBER(G29),B29<G29,FALSE) | T29: =OR(O29,P29,Q29,R29,S29)
A30: =IF(Prices!A30="","",Prices!A30) | B30: =IF(Prices!E30="","",Prices!E30) | C30: =IF(Prices!C30="","",Prices!C30) | D30: =IF(Prices!D30="","",Prices!D30) | G30: =AVERAGE(B11:B30)-2*STDEV.P(B11:B30) | H30: =MAX(B30-B29,0) | I30: =MAX(B29-B30,0) | J30: =(J29*13+H30)/14 | K30: =(K29*13+I30)/14 | L30: =IF(K30=0,100,100-100/(1+J30/K30)) | M30: =IF(MAX(C17:C30)=MIN(D17:D30),50,100*(B30-MIN(D17:D30))/(MAX(C17:C30)-MIN(D17:D30))) | N30: =AVERAGE(M28:M30) | O30: =IF(ISNUMBER(L30),L30<30,FALSE) | P30: =IF(ISNUMBER(N30),N30<20,FALSE) | Q30: =FALSE | R30: =FALSE | S30: =IF(ISNUMBER(G30),B30<G30,FALSE) | T30: =OR(O30,P30,Q30,R30,S30)
A31: =IF(Prices!A31="","",Prices!A31) | B31: =IF(Prices!E31="","",Prices!E31) | C31: =IF(Prices!C31="","",Prices!C31) | D31: =IF(Prices!D31="","",Prices!D31) | G31: =AVERAGE(B12:B31)-2*STDEV.P(B12:B31) | H31: =MAX(B31-B30,0) | I31: =MAX(B30-B31,0) | J31: =(J30*13+H31)/14 | K31: =(K30*13+I31)/14 | L31: =IF(K31=0,100,100-100/(1+J31/K31)) | M31: =IF(MAX(C18:C31)=MIN(D18:D31),50,100*(B31-MIN(D18:D31))/(MAX(C18:C31)-MIN(D18:D31))) | N31: =AVERAGE(M29:M31) | O31: =IF(ISNUMBER(L31),L31<30,FALSE) | P31: =IF(ISNUMBER(N31),N31<20,FALSE) | Q31: =FALSE | R31: =FALSE | S31: =IF(ISNUMBER(G31),B31<G31,FALSE) | T31: =OR(O31,P31,Q31,R31,S31)
A32: =IF(Prices!A32="","",Prices!A32) | B32: =IF(Prices!E32="","",Prices!E32) | C32: =IF(Prices!C32="","",Prices!C32) | D32: =IF(Prices!D32="","",Prices!D32) | G32: =AVERAGE(B13:B32)-2*STDEV.P(B13:B32) | H32: =MAX(B32-B31,0) | I32: =MAX(B31-B32,0) | J32: =(J31*13+H32)/14 | K32: =(K31*13+I32)/14 | L32: =IF(K32=0,100,100-100/(1+J32/K32)) | M32: =IF(MAX(C19:C32)=MIN(D19:D32),50,100*(B32-MIN(D19:D32))/(MAX(C19:C32)-MIN(D19:D32))) | N32: =AVERAGE(M30:M32) | O32: =IF(ISNUMBER(L32),L32<30,FALSE) | P32: =IF(ISNUMBER(N32),N32<20,FALSE) | Q32: =FALSE | R32: =FALSE | S32: =IF(ISNUMBER(G32),B32<G32,FALSE) | T32: =OR(O32,P32,Q32,R32,S32)
... A50: =IF(Prices!A50="","",Prices!A50) | B50: =IF(Prices!E50="","",Prices!E50) | C50: =IF(Prices!C50="","",Prices!C50) | D50: =IF(Prices!D50="","",Prices!D50) | G50: =AVERAGE(B31:B50)-2*STDEV.P(B31:B50) | H50: =MAX(B50-B49,0) | I50: =MAX(B49-B50,0) | J50: =(J49*13+H50)/14 | K50: =(K49*13+I50)/14 | L50: =IF(K50=0,100,100-100/(1+J50/K50)) | M50: =IF(MAX(C37:C50)=MIN(D37:D50),50,100*(B50-MIN(D37:D50))/(MAX(C37:C50)-MIN(D37:D50))) | N50: =AVERAGE(M48:M50) | O50: =IF(ISNUMBER(L50),L50<30,FALSE) | P50: =IF(ISNUMBER(N50),N50<20,FALSE) | Q50: =FALSE | R50: =FALSE | S50: =IF(ISNUMBER(G50),B50<G50,FALSE) | T50: =OR(O50,P50,Q50,R50,S50)
A51: =IF(Prices!A51="","",Prices!A51) | B51: =IF(Prices!E51="","",Prices!E51) | C51: =IF(Prices!C51="","",Prices!C51) | D51: =IF(Prices!D51="","",Prices!D51) | E51: =AVERAGE(B2:B51) | G51: =AVERAGE(B32:B51)-2*STDEV.P(B32:B51) | H51: =MAX(B51-B50,0) | I51: =MAX(B50-B51,0) | J51: =(J50*13+H51)/14 | K51: =(K50*13+I51)/14 | L51: =IF(K51=0,100,100-100/(1+J51/K51)) | M51: =IF(MAX(C38:C51)=MIN(D38:D51),50,100*(B51-MIN(D38:D51))/(MAX(C38:C51)-MIN(D38:D51))) | N51: =AVERAGE(M49:M51) | O51: =IF(ISNUMBER(L51),L51<30,FALSE) | P51: =IF(ISNUMBER(N51),N51<20,FALSE) | Q51: =FALSE | R51: =FALSE | S51: =IF(ISNUMBER(G51),B51<G51,FALSE) | T51: =OR(O51,P51,Q51,R51,S51)
A52: =IF(Prices!A52="","",Prices!A52) | B52: =IF(Prices!E52="","",Prices!E52) | C52: =IF(Prices!C52="","",Prices!C52) | D52: =IF(Prices!D52="","",Prices!D52) | E52: =AVERAGE(B3:B52) | G52: =AVERAGE(B33:B52)-2*STDEV.P(B33:B52) | H52: =MAX(B52-B51,0) | I52: =MAX(B51-B52,0) | J52: =(J51*13+H52)/14 | K52: =(K51*13+I52)/14 | L52: =IF(K52=0,100,100-100/(1+J52/K52)) | M52: =IF(MAX(C39:C52)=MIN(D39:D52),50,100*(B52-MIN(D39:D52))/(MAX(C39:C52)-MIN(D39:D52))) | N52: =AVERAGE(M50:M52) | O52: =IF(ISNUMBER(L52),L52<30,FALSE) | P52: =IF(ISNUMBER(N52),N52<20,FALSE) | Q52: =FALSE | R52: =FALSE | S52: =IF(ISNUMBER(G52),B52<G52,FALSE) | T52: =OR(O52,P52,Q52,R52,S52)
A53: =IF(Prices!A53="","",Prices!A53) | B53: =IF(Prices!E53="","",Prices!E53) | C53: =IF(Prices!C53="","",Prices!C53) | D53: =IF(Prices!D53="","",Prices!D53) | E53: =AVERAGE(B4:B53) | G53: =AVERAGE(B34:B53)-2*STDEV.P(B34:B53) | H53: =MAX(B53-B52,0) | I53: =MAX(B52-B53,0) | J53: =(J52*13+H53)/14 | K53: =(K52*13+I53)/14 | L53: =IF(K53=0,100,100-100/(1+J53/K53)) | M53: =IF(MAX(C40:C53)=MIN(D40:D53),50,100*(B53-MIN(D40:D53))/(MAX(C40:C53)-MIN(D40:D53))) | N53: =AVERAGE(M51:M53) | O53: =IF(ISNUMBER(L53),L53<30,FALSE) | P53: =IF(ISNUMBER(N53),N53<20,FALSE) | Q53: =FALSE | R53: =FALSE | S53: =IF(ISNUMBER(G53),B53<G53,FALSE) | T53: =OR(O53,P53,Q53,R53,S53)
A54: =IF(Prices!A54="","",Prices!A54) | B54: =IF(Prices!E54="","",Prices!E54) | C54: =IF(Prices!C54="","",Prices!C54) | D54: =IF(Prices!D54="","",Prices!D54) | E54: =AVERAGE(B5:B54) | G54: =AVERAGE(B35:B54)-2*STDEV.P(B35:B54) | H54: =MAX(B54-B53,0) | I54: =MAX(B53-B54,0) | J54: =(J53*13+H54)/14 | K54: =(K53*13+I54)/14 | L54: =IF(K54=0,100,100-100/(1+J54/K54)) | M54: =IF(MAX(C41:C54)=MIN(D41:D54),50,100*(B54-MIN(D41:D54))/(MAX(C41:C54)-MIN(D41:D54))) | N54: =AVERAGE(M52:M54) | O54: =IF(ISNUMBER(L54),L54<30,FALSE) | P54: =IF(ISNUMBER(N54),N54<20,FALSE) | Q54: =FALSE | R54: =FALSE | S54: =IF(ISNUMBER(G54),B54<G54,FALSE) | T54: =OR(O54,P54,Q54,R54,S54)
A55: =IF(Prices!A55="","",Prices!A55) | B55: =IF(Prices!E55="","",Prices!E55) | C55: =IF(Prices!C55="","",Prices!C55) | D55: =IF(Prices!D55="","",Prices!D55) | E55: =AVERAGE(B6:B55) | G55: =AVERAGE(B36:B55)-2*STDEV.P(B36:B55) | H55: =MAX(B55-B54,0) | I55: =MAX(B54-B55,0) | J55: =(J54*13+H55)/14 | K55: =(K54*13+I55)/14 | L55: =IF(K55=0,100,100-100/(1+J55/K55)) | M55: =IF(MAX(C42:C55)=MIN(D42:D55),50,100*(B55-MIN(D42:D55))/(MAX(C42:C55)-MIN(D42:D55))) | N55: =AVERAGE(M53:M55) | O55: =IF(ISNUMBER(L55),L55<30,FALSE) | P55: =IF(ISNUMBER(N55),N55<20,FALSE) | Q55: =FALSE | R55: =FALSE | S55: =IF(ISNUMBER(G55),B55<G55,FALSE) | T55: =OR(O55,P55,Q55,R55,S55)
A56: =IF(Prices!A56="","",Prices!A56) | B56: =IF(Prices!E56="","",Prices!E56) | C56: =IF(Prices!C56="","",Prices!C56) | D56: =IF(Prices!D56="","",Prices!D56) | E56: =AVERAGE(B7:B56) | G56: =AVERAGE(B37:B56)-2*STDEV.P(B37:B56) | H56: =MAX(B56-B55,0) | I56: =MAX(B55-B56,0) | J56: =(J55*13+H56)/14 | K56: =(K55*13+I56)/14 | L56: =IF(K56=0,100,100-100/(1+J56/K56)) | M56: =IF(MAX(C43:C56)=MIN(D43:D56),50,100*(B56-MIN(D43:D56))/(MAX(C43:C56)-MIN(D43:D56))) | N56: =AVERAGE(M54:M56) | O56: =IF(ISNUMBER(L56),L56<30,FALSE) | P56: =IF(ISNUMBER(N56),N56<20,FALSE) | Q56: =FALSE | R56: =FALSE | S56: =IF(ISNUMBER(G56),B56<G56,FALSE) | T56: =OR(O56,P56,Q56,R56,S56)
A57: =IF(Prices!A57="","",Prices!A57) | B57: =IF(Prices!E57="","",Prices!E57) | C57: =IF(Prices!C57="","",Prices!C57) | D57: =IF(Prices!D57="","",Prices!D57) | E57: =AVERAGE(B8:B57) | G57: =AVERAGE(B38:B57)-2*STDEV.P(B38:B57) | H57: =MAX(B57-B56,0) | I57: =MAX(B56-B57,0) | J57: =(J56*13+H57)/14 | K57: =(K56*13+I57)/14 | L57: =IF(K57=0,100,100-100/(1+J57/K57)) | M57: =IF(MAX(C44:C57)=MIN(D44:D57),50,100*(B57-MIN(D44:D57))/(MAX(C44:C57)-MIN(D44:D57))) | N57: =AVERAGE(M55:M57) | O57: =IF(ISNUMBER(L57),L57<30,FALSE) | P57: =IF(ISNUMBER(N57),N57<20,FALSE) | Q57: =FALSE | R57: =FALSE | S57: =IF(ISNUMBER(G57),B57<G57,FALSE) | T57: =OR(O57,P57,Q57,R57,S57)
...
